Workbook
Name \0: #REF!
Name \a: #REF!
Name \b: #REF!
Name \c: #REF!
Name \d: #REF!
Name \e: #REF!
Name \f: #REF!
Name \g: #REF!
Name \h: #REF!
Name \i: #REF!
Name \j: #REF!
Name \k: #REF!
Name \l: #REF!
Name \n: #REF!
Name \p: #REF!
Name \s: #REF!
Name \t: #REF!
Name \v: #REF!
Name \w: #REF!
Name \x: #REF!
Name \z: #REF!
Name ____________D65590: #REF!
Name ___________D65590: #REF!
Name __________D65590: #REF!
Name _________C65550: #REF!
Name _________C65590: #REF!
Name _________C65690: #REF!
Name _________C68800: #REF!
Name _________C69000: #REF!
Name _________C75500: #REF!
Name _________C80500: #REF!
Name _________D65590: #REF!
Name ________C65550: #REF!
Name ________C65590: #REF!
Name ________C65690: #REF!
Name ________C68800: #REF!
Name ________C69000: #REF!
Name ________C75500: #REF!
Name ________C80500: #REF!
Name ________D65590: #REF!
Name ________NHR1: #REF!
Name ________obj05: #REF!
Name ________rm1: #REF!
Name _______C65550: #REF!
Name _______C65590: #REF!
Name _______C65690: #REF!
Name _______C68800: #REF!
Name _______C69000: #REF!
Name _______C75500: #REF!
Name _______C80500: #REF!
Name _______D65590: #REF!
Name _______NHR1: #REF!
Name _______obj05: #REF!
Name _______OBJ2005: #REF!
Name _______rm1: #REF!
Name ______C65550: #REF!
Name ______C65590: #REF!
Name ______C65690: #REF!
Name ______C68800: #REF!
Name ______C69000: #REF!

Sheet EF TGO AR4
B2: ชื่อ | C2: Units | D2: EMISSION FACTORS | H2: แหล่งอ้างอิงข้อมูล | J2: GWP100
D3: CO2 | E3: CH4 | F3: N2O | G3: Total | J3: ที่มา | K3: IPCC, AR4 | L3: IPCC, AR5
D4: [kg CO2/unit] | E4: [kg CH4/unit] | F4: [kg N2O/unit] | G4: [kg CO2eq/unit] | J4: CO2 | K4: 1 | L4: 1
A5: Stationary Combustion | J5: CH4 | K5: 25 | L5: 28
B6: Natural gas | C6: scf | D6: =D48*$G$48*10^-6 -> 0.057222 | E6: =E48*$G$48*10^-6 -> 1.02e-06 | F6: =F48*$G$48*10^-6 -> 1.02e-07 | G6: =D6+(E6*$K$5)+(F6*$K$6) -> 0.057277896 | H6: IPCC Vol.2 table 2.2, DEDE | J6: N2O | K6: 298 | L6: 265
B7: Natural gas | C7: MJ | D7: =D48/1000000 -> 0.0561 | E7: =E48/1000000 -> 1e-06 | F7: =F48/1000000 -> 1e-07 | G7: =D7+(E7*$K$5)+(F7*$K$6) -> 0.0561548 | H7: IPCC Vol.2 table 2.2, DEDE | J7: SF6 | K7: 22800 | L7: 23500
B8: Lignite | C8: kg | D8: =D49*$G$49*10^-6 -> 1.05747 | E8: =E49*$G$49*10^-6 -> 1.047e-05 | F8: =F49*$G$49*10^-6 -> 1.5705e-05 | G8: =D8+(E8*$K$5)+(F8*$K$6) -> 1.0624118 | H8: IPCC Vol.2 table 2.2, DEDE | J8: NF3 | K8: 17200 | L8: 16100
B9: Fuel oil A | C9: litre | D9: =D50*$G$50*10^-6 -> 3.2096984 | E9: =E50*$G$50*10^-6 -> 0.00012440692 | F9: =F50*$G$50*10^-6 -> 2.4881383e-05 | G9: =D9+(E9*$K$5)+(F9*$K$6) -> 3.2202233 | H9: IPCC Vol.2 table 2.2, PTT | J9: PASS: 12345678
B10: Fuel oil C | C10: litre | D10: =D51*$G$51*10^-6 -> 3.2353401 | E10: =E51*$G$51*10^-6 -> 0.00012540078 | F10: =F51*$G$51*10^-6 -> 2.5080156e-05 | G10: =D10+(E10*$K$5)+(F10*$K$6) -> 3.245949 | H10: IPCC Vol.2 table 2.2, PTT
B11: Gas/Diesel oil | C11: litre | D11: =D52*$G$52*10^-6 -> 2.698722 | E11: =E52*$G$52*10^-6 -> 0.00010926 | F11: =F52*$G$52*10^-6 -> 2.1852e-05 | G11: =D11+(E11*$K$5)+(F11*$K$6) -> 2.7079654 | H11: IPCC Vol.2 table 2.2, DEDE
B12: Anthracite | C12: kg | D12: =D53*$G$53*10^-6 -> 3.08662 | E12: =E53*$G$53*10^-6 -> 3.14e-05 | F12: =F53*$G$53*10^-6 -> 4.71e-05 | G12: =D12+(E12*$K$5)+(F12*$K$6) -> 3.1014408 | H12: IPCC Vol.2 table 2.2, DEDE
B13: Sub-bituminous coal | C13: kg | D13: =D54*$G$54*10^-6 -> 2.534157 | E13: =E54*$G$54*10^-6 -> 2.637e-05 | F13: =F54*$G$54*10^-6 -> 3.9555e-05 | G13: =D13+(E13*$K$5)+(F13*$K$6) -> 2.5466036 | H13: IPCC Vol.2 table 2.2, DEDE
B14: Jet Kerosene | C14: litre | D14: =D55*$G$55*10^-6 -> 2.468895 | E14: =E55*$G$55*10^-6 -> 0.00010359 | F14: =F55*$G$55*10^-6 -> 2.0718e-05 | G14: =D14+(E14*$K$5)+(F14*$K$6) -> 2.4776587 | H14: IPCC Vol.2 table 2.2, DEDE
B15: LPG | C15: litre | D15: =D56*$G$56*10^-6 -> 1.679722 | E15: =E56*$G$56*10^-6 -> 2.662e-05 | F15: =F56*$G$56*10^-6 -> 2.662e-06 | G15: =D15+(E15*$K$5)+(F15*$K$6) -> 1.6811808 | H15: IPCC Vol.2 table 2.2, DEDE
B16: LPG | C16: kg | D16: =D15/0.54 -> 3.1105963 | E16: =E15/0.54 -> 4.9296296e-05 | F16: =F15/0.54 -> 4.9296296e-06 | G16: =D16+(E16*$K$5)+(F16*$K$6) -> 3.1132977 | H16: IPCC Vol.2 table 2.2, DEDE LPG 1 litre = 0.54 kg
B17: Motor gasoline | C17: litre | D17: =D57*$G$57*10^-6 -> 2.181564 | E17: =E57*$G$57*10^-6 -> 9.444e-05 | F17: =F57*$G$57*10^-6 -> 1.8888e-05 | G17: =D17+(E17*$K$5)+(F17*$K$6) -> 2.1895536 | H17: IPCC Vol.2 table 2.2, DEDE
A19: Mobile Combustion (On road)
B20: Motor Gasoline - uncontrolled | C20: litre | D20: =D63*$G$63*10^-6 -> 2.181564 | E20: =E63*$G$63*10^-6 -> 0.00103884 | F20: =F63*$G$63*10^-6 -> 0.000100736 | G20: =D20+(E20*$K$5)+(F20*$K$6) -> 2.2375543 | H20: IPCC Vol.2 table 3.2.1, 3.2.2, DEDE
B21: Motor Gasoline - oxydation catalyst | C21: litre | D21: =D64*$G$64*10^-6 -> 2.181564 | E21: =E64*$G$64*10^-6 -> 0.000787 | F21: =F64*$G$64*10^-6 -> 0.00025184 | G21: =D21+(E21*$K$5)+(F21*$K$6) -> 2.2762873 | H21: IPCC Vol.2 table 3.2.1, 3.2.2, DEDE
B22: Motor Gasoline - low mileage light duty vihicle vintage 1995 or later | C22: litre | D22: =D65*$G$65*10^-6 -> 2.181564 | E22: =E65*$G$65*10^-6 -> 0.000119624 | F22: =F65*$G$65*10^-6 -> 0.000179436 | G22: =D22+(E22*$K$5)+(F22*$K$6) -> 2.2380265 | H22: IPCC Vol.2 table 3.2.1, 3.2.2, DEDE
B23: Gas/ Diesel Oil | C23: litre | D23: =D66*$G$66*10^-6 -> 2.698722 | E23: =E66*$G$66*10^-6 -> 0.000142038 | F23: =F66*$G$66*10^-6 -> 0.000142038 | G23: =D23+(E23*$K$5)+(F23*$K$6) -> 2.7446003 | H23: IPCC Vol.2 table 3.2.1, 3.2.2, DEDE
B24: Compressed Natural Gas | C24: kg | D24: =D67*$G$67*10^-6 -> 2.12619 | E24: =E67*$G$67*10^-6 -> 0.0034868 | F24: =F67*$G$67*10^-6 -> 0.0001137 | G24: =D24+(E24*$K$5)+(F24*$K$6) -> 2.2472426 | H24: IPCC Vol.2 table 3.2.1, 3.2.2, PTT
B25: Liquified Petroleum Gas | C25: litre | D25: =D68*$G$68*10^-6 -> 1.679722 | E25: =E68*$G$68*10^-6 -> 0.00165044 | F25: =F68*$G$68*10^-6 -> 5.324e-06 | G25: =D25+(E25*$K$5)+(F25*$K$6) -> 1.7225696 | H25: IPCC Vol.2 table 3.2.1, 3.2.2, DEDE
B26: Liquified Petroleum Gas | C26: kg | D26: =D25/0.54 -> 3.1105963 | E26: =E25/0.54 -> 0.0030563704 | F26: =F25/0.54 -> 9.8592593e-06 | G26: =D26+(E26*$K$5)+(F26*$K$6) -> 3.1899436 | H26: IPCC Vol.2 table 3.2.1, 3.2.2, DEDE LPG 1 litre = 0.54 kg
A27: Mobile Combustion (Off road)
B28: Diesel
B29: - Agriculture | C29: litre | D29: =D75*$G$75/(10^6) -> 2.698722 | E29: =E75*$G$75/(10^6) -> 0.000151143 | F29: =F75*$G$75/(10^6) -> 0.001041612 | G29: =D29+(E29*$K$5)+(F29*$K$6) -> 3.012901 | H29: IPCC Vol.2 table 3.3.1, DEDE
B30: - Forestry | C30: litre | D30: =D76*$G$76/(10^6) -> 2.698722 | E30: =E76*$G$76/(10^6) -> 0.000151143 | F30: =F76*$G$76/(10^6) -> 0.001041612 | G30: =D30+(E30*$K$5)+(F30*$K$6) -> 3.012901 | H30: IPCC Vol.2 table 3.3.1, DEDE
B31: - Industry | C31: litre | D31: =D77*$G$77/(10^6) -> 2.698722 | E31: =E77*$G$77/(10^6) -> 0.000151143 | F31: =F77*$G$77/(10^6) -> 0.001041612 | G31: =D31+(E31*$K$5)+(F31*$K$6) -> 3.012901 | H31: IPCC Vol.2 table 3.3.1, DEDE
B32: - Household | C32: litre | D32: =D78*$G$78/(10^6) -> 2.698722 | E32: =E78*$G$78/(10^6) -> 0.000151143 | F32: =F78*$G$78/(10^6) -> 0.001041612 | G32: =D32+(E32*$K$5)+(F32*$K$6) -> 3.012901 | H32: IPCC Vol.2 table 3.3.1, DEDE
B33: Motor Gasoline - 4 stroke
B34: - Agriculture | C34: litre | D34: =D80*$G$80/(10^6) -> 2.181564 | E34: =E80*$G$80/(10^6) -> 0.0025184 | F34: =F80*$G$80/(10^6) -> 6.296e-05 | G34: =D34+(E34*$K$5)+(F34*$K$6) -> 2.2632861 | H34: IPCC Vol.2 table 3.3.1, DEDE
B35: - Forestry | C35: litre | D35: =D81*$G$81/(10^6) -> 2.181564 | E35: =E81*$G$81/(10^6) -> 0 | F35: =F81*$G$81/(10^6) -> 0 | G35: =D35+(E35*$K$5)+(F35*$K$6) -> 2.181564 | H35: IPCC Vol.2 table 3.3.1, DEDE
B36: - Industry | C36: litre | D36: =D82*$G$82/(10^6) -> 2.181564 | E36: =E82*$G$82/(10^6) -> 0.001574 | F36: =F82*$G$82/(10^6) -> 6.296e-05 | G36: =D36+(E36*$K$5)+(F36*$K$6) -> 2.2396761 | H36: IPCC Vol.2 table 3.3.1, DEDE
B37: - Household | C37: litre | D37: =D83*$G$83/(10^6) -> 2.181564 | E37: =E83*$G$83/(10^6) -> 0.0037776 | F37: =F83*$G$83/(10^6) -> 6.296e-05 | G37: =D37+(E37*$K$5)+(F37*$K$6) -> 2.2947661 | H37: IPCC Vol.2 table 3.3.1, DEDE
B38: Motor Gasoline - 2 stroke
B39: - Agriculture | C39: litre | D39: =D85*$G$85/(10^6) -> 2.181564 | E39: =E85*$G$85/(10^6) -> 0.0044072 | F39: =F85*$G$85/(10^6) -> 1.2592e-05 | G39: =D39+(E39*$K$5)+(F39*$K$6) -> 2.2954964 | H39: IPCC Vol.2 table 3.3.1, DEDE
B40: - Forestry | C40: litre | D40: =D86*$G$86/(10^6) -> 2.181564 | E40: =E86*$G$86/(10^6) -> 0.0053516 | F40: =F86*$G$86/(10^6) -> 1.2592e-05 | G40: =D40+(E40*$K$5)+(F40*$K$6) -> 2.3191064 | H40: IPCC Vol.2 table 3.3.1, DEDE
B41: - Industry | C41: litre | D41: =D87*$G$87/(10^6) -> 2.181564 | E41: =E87*$G$87/(10^6) -> 0.0040924 | F41: =F87*$G$87/(10^6) -> 1.2592e-05 | G41: =D41+(E41*$K$5)+(F41*$K$6) -> 2.2876264 | H41: IPCC Vol.2 table 3.3.1, DEDE
B42: - Household | C42: litre | D42: =D88*$G$88/(10^6) -> 2.181564 | E42: =E88*$G$88/(10^6) -> 0.0056664 | F42: =F88*$G$88/(10^6) -> 1.2592e-05 | G42: =D42+(E42*$K$5)+(F42*$K$6) -> 2.3269764 | H42: IPCC Vol.2 table 3.3.1, DEDE
...

Sheet Excel sheet-Head Office
B1: บัญชีรายการก๊าซเรือนกระจก | AO1: TCFO_R_01 Version 04 : 21/2/2020
B3: ชื่อฟอร์ม | C3: บัญชีรายการก๊าซเรือนกระจก | H3: องค์กร | AB3: ปีที่เก็บข้อมูล | AO3: หน้าที่ | AR3: 4
B4: รหัสฟอร์ม | C4: Fr-04.1 | H4: ผู้จัดทำ | AO4: วันที่
A6: ขอบเขต | B6: รายการ | C6: ค่า LCI | E6: GHG ที่ต้องรายงานตามข้อกำหนด | O6: GHG ที่อยู่นอกข้อกำหนด | Q6: Total (kgCO2e/หน่วย) | R6: ที่มา | Y6: Subsitute | Z6: แหล่งอ้างอิง | AA6: ผลคูณ (Ton GHG) | AG6: ผลคูณ (TonCO2e) | AO6: Total GHG | AP6: สัดส่วน (%) | AQ6: สัดส่วน (%) (SCOPE 1+2) | AR6: สัดส่วน (%) (SCOPE 1+2+3) | AS6: คำอธิบายเพิ่มเติม | AU6: GWP100
R7: 1st | T7: 2nd | X7: Other | AU7: ที่มา | AV7: IPCC, AR5
E8: ค่า EF (kg GHG/หน่วย) | M8: GWP100 | O8: ค่า EF (kg GHG/หน่วย) | P8: GWP100 | R8: Self collct | S8: Supplier | T8: TH LCI DB | U8: TGO EF | V8: Thai Res. | W8: Int. DB | AO8: (TonCO2e) | AU8: CO2 | AV8: 1
C9: หน่วย | D9: ปริมาณ | E9: CO2 | F9: Fossil CH4 | G9: CH4 | H9: N2O | I9: SF6 | J9: NF3 | K9: HFCs | L9: PFCs | M9: HFCs | N9: PFCs | AA9: CO2 | AB9: Fossil CH4 | AC9: CH4 | AD9: N2O | AE9: SF6 | AF9: NF3 | AG9: Fossil CH4 | AH9: CH4 | AI9: N2O | AJ9: SF6 | AK9: NF3 | AL9: HFCs | AM9: PFCs | AN9: Other | AU9: Fossil CH4 | AV9: 30
A10: ขอบเขต 1 | B10: 1.การปล่อยก๊าซเรือนกระจกที่เกิดขึ้นจากการเผาไหม้อยู่กับที่ (Stationary Combustion) | AA10: =D10*E10/1000 -> 0 | AB10: =D10*F10/1000 -> 0 | AC10: =D10*G10/1000 -> 0 | AD10: =D10*H10/1000 -> 0 | AE10: =D10*I10/1000 -> 0 | AF10: =D10*J10/1000 -> 0 | AG10: =D10*F10*$AV$9/1000 -> 0 | AH10: =D10*G10*$AV$10/1000 -> 0 | AI10: =D10*H10*$AV$11/1000 -> 0 | AJ10: =D10*I10*$AV$12/1000 -> 0 | AK10: =D10*J10*$AV$13/1000 -> 0 | AL10: =D10*K10*M10/1000 -> 0 | AM10: =D10*L10*N10/1000 -> 0 | AO10: =D10*Q10/1000 -> 0 | AP10: =AO10/$AO$29 -> #REF! | AQ10: =AO10/$AO$95 -> #REF! | AR10: =AP10/$AO$96 -> #REF! | AU10: CH4 | AV10: 28
B11: n/a | AA11: =D11*E11/1000 -> 0 | AB11: =D11*F11/1000 -> 0 | AC11: =D11*G11/1000 -> 0 | AD11: =D11*H11/1000 -> 0 | AE11: =D11*I11/1000 -> 0 | AF11: =D11*J11/1000 -> 0 | AG11: =D11*F11*$AV$9/1000 -> 0 | AH11: =D11*G11*$AV$10/1000 -> 0 | AI11: =D11*H11*$AV$11/1000 -> 0 | AJ11: =D11*I11*$AV$12/1000 -> 0 | AK11: =D11*J11*$AV$13/1000 -> 0 | AL11: =D11*K11*M11/1000 -> 0 | AM11: =D11*L11*N11/1000 -> 0 | AO11: =D11*Q11/1000 -> 0 | AP11: =AO11/$AO$29 -> #REF! | AQ11: =AO11/$AO$95 -> #REF! | AR11: =AO11/$AO$96 -> #REF! | AU11: N2O | AV11: 265
B12: 2.การปล่อยก๊าซเรือนกระจกที่เกิดขึ้นจากการเผาไหม้แบบเคลื่อนที่ (Mobile Combustion) | AA12: =D12*E12/1000 -> 0 | AB12: =D12*F12/1000 -> 0 | AC12: =D12*G12/1000 -> 0 | AD12: =D12*H12/1000 -> 0 | AE12: =D12*I12/1000 -> 0 | AF12: =D12*J12/1000 -> 0 | AG12: =D12*F12*$AV$9/1000 -> 0 | AH12: =D12*G12*$AV$10/1000 -> 0 | AI12: =D12*H12*$AV$11/1000 -> 0 | AJ12: =D12*I12*$AV$12/1000 -> 0 | AK12: =D12*J12*$AV$13/1000 -> 0 | AL12: =D12*K12*M12/1000 -> 0 | AM12: =D12*L12*N12/1000 -> 0 | AO12: =D12*Q12/1000 -> 0 | AP12: =AO12/$AO$29 -> #REF! | AQ12: =AO12/$AO$95 -> #REF! | AR12: =AO12/$AO$96 -> #REF!
B13: ='Activity data -Head Office'!A10 -> Diesel B7 รถ forklift | C13: ='Activity data -Head Office'!E10 -> Litre | D13: ='Activity data -Head Office'!F10 -> 627.63 | E13: =#REF! -> #REF! | F13: =#REF! -> #REF! | G13: =#REF! -> #REF! | H13: =#REF! -> #REF! | I13: 0 | J13: 0 | K13: 0 | L13: 0 | M13: 0 | N13: 0 | Q13: =(E13*$AV$8)+(F13*$AV$9)+(G13*$AV$10)+(H13*$AV$11)+(I13*$AV$12)+(J13*$AV$13)+(K13*M13)+(L13*N13) -> #REF! | U13: x | Z13: EF_CFO_Diesel-Industry [Moblie combustion] | AA13: =D13*E13/1000 -> #REF! | AB13: =D13*F13/1000 -> #REF! | AC13: =D13*G13/1000 -> #REF! | AD13: =D13*H13/1000 -> #REF! | AE13: =D13*I13/1000 -> 0 | AF13: =D13*J13/1000 -> 0 | AG13: =D13*F13*$AV$9/1000 -> #REF! | AH13: =D13*G13*$AV$10/1000 -> #REF! | AI13: =D13*H13*$AV$11/1000 -> #REF! | AJ13: =D13*I13*$AV$12/1000 -> 0 | AK13: =D13*J13*$AV$13/1000 -> 0 | AL13: =D13*K13*M13/1000 -> 0 | AM13: =D13*L13*N13/1000 -> 0 | AO13: =D13*Q13/1000 -> #REF! | AP13: =AO13/$AO$29 -> #REF! | AQ13: =AO13/$AO$95 -> #REF! | AR13: =AO13/$AO$96 -> #REF!
B14: ='Activity data -Head Office'!A11 -> Diesel B7 รถบรรทุก 6 ล้อ (บท9680, 83-9095) | C14: ='Activity data -Head Office'!E11 -> Litre | D14: ='Activity data -Head Office'!F11 -> 8786.38 | E14: =#REF! -> #REF! | F14: =#REF! -> #REF! | G14: =#REF! -> #REF! | H14: =#REF! -> #REF! | I14: 0 | J14: 0 | K14: 0 | L14: 0 | M14: 0 | N14: 0 | Q14: =(E14*$AV$8)+(F14*$AV$9)+(G14*$AV$10)+(H14*$AV$11)+(I14*$AV$12)+(J14*$AV$13)+(K14*M14)+(L14*N14) -> #REF! | U14: x | Z14: EF_CFO_Diesel-Industry [Moblie combustion] | AA14: =D14*E14/1000 -> #REF! | AB14: =D14*F14/1000 -> #REF! | AC14: =D14*G14/1000 -> #REF! | AD14: =D14*H14/1000 -> #REF! | AE14: =D14*I14/1000 -> 0 | AF14: =D14*J14/1000 -> 0 | AG14: =D14*F14*$AV$9/1000 -> #REF! | AH14: =D14*G14*$AV$10/1000 -> #REF! | AI14: =D14*H14*$AV$11/1000 -> #REF! | AJ14: =D14*I14*$AV$12/1000 -> 0 | AK14: =D14*J14*$AV$13/1000 -> 0 | AL14: =D14*K14*M14/1000 -> 0 | AM14: =D14*L14*N14/1000 -> 0 | AO14: =D14*Q14/1000 -> #REF! | AP14: =AO14/$AO$29 -> #REF! | AQ14: =AO14/$AO$95 -> #REF! | AR14: =AO14/$AO$96 -> #REF!
B15: ='Activity data -Head Office'!A12 -> Diesel B7 รถกระบะส่วนบุคคลขนาด 1 ตัน ของบริษัท (1กร 3494) | C15: ='Activity data -Head Office'!E12 -> Litre | D15: ='Activity data -Head Office'!F12 -> 2991.31 | E15: =#REF! -> #REF! | F15: =#REF! -> #REF! | G15: =#REF! -> #REF! | H15: =#REF! -> #REF! | I15: 0 | J15: 0 | K15: 0 | L15: 0 | M15: 0 | N15: 0 | Q15: =(E15*$AV$8)+(F15*$AV$9)+(G15*$AV$10)+(H15*$AV$11)+(I15*$AV$12)+(J15*$AV$13)+(K15*M15)+(L15*N15) -> #REF! | U15: x | Z15: EF_CFO_Diesel [Moblie combustion] | AA15: =D15*E15/1000 -> #REF! | AB15: =D15*F15/1000 -> #REF! | AC15: =D15*G15/1000 -> #REF! | AD15: =D15*H15/1000 -> #REF! | AE15: =D15*I15/1000 -> 0 | AF15: =D15*J15/1000 -> 0 | AG15: =D15*F15*$AV$9/1000 -> #REF! | AH15: =D15*G15*$AV$10/1000 -> #REF! | AI15: =D15*H15*$AV$11/1000 -> #REF! | AJ15: =D15*I15*$AV$12/1000 -> 0 | AK15: =D15*J15*$AV$13/1000 -> 0 | AL15: =D15*K15*M15/1000 -> 0 | AM15: =D15*L15*N15/1000 -> 0 | AO15: =D15*Q15/1000 -> #REF! | AP15: =AO15/$AO$29 -> #REF! | AQ15: =AO15/$AO$95 -> #REF! | AR15: =AO15/$AO$96 -> #REF!
B16: ='Activity data -Head Office'!A13 -> Diesel B7/พรีเมียม รถยนต์ขนาดใหญ่ 2000 cc (4ขอ 1948, 6กญ 2678, ญร4569, ภฮ9789) | C16: ='Activity data -Head Office'!E13 -> Litre | D16: ='Activity data -Head Office'!F13 -> 2881.42 | E16: =#REF! -> #REF! | F16: =#REF! -> #REF! | G16: =#REF! -> #REF! | H16: =#REF! -> #REF! | I16: 0 | J16: 0 | K16: 0 | L16: 0 | M16: 0 | N16: 0 | Q16: =(E16*$AV$8)+(F16*$AV$9)+(G16*$AV$10)+(H16*$AV$11)+(I16*$AV$12)+(J16*$AV$13)+(K16*M16)+(L16*N16) -> #REF! | U16: x | Z16: EF_CFO_Diesel [Moblie combustion] | AA16: =D16*E16/1000 -> #REF! | AB16: =D16*F16/1000 -> #REF! | AC16: =D16*G16/1000 -> #REF! | AD16: =D16*H16/1000 -> #REF! | AE16: =D16*I16/1000 -> 0 | AF16: =D16*J16/1000 -> 0 | AG16: =D16*F16*$AV$9/1000 -> #REF! | AH16: =D16*G16*$AV$10/1000 -> #REF! | AI16: =D16*H16*$AV$11/1000 -> #REF! | AJ16: =D16*I16*$AV$12/1000 -> 0 | AK16: =D16*J16*$AV$13/1000 -> 0 | AL16: =D16*K16*M16/1000 -> 0 | AM16: =D16*L16*N16/1000 -> 0 | AO16: =D16*Q16/1000 -> #REF! | AP16: =AO16/$AO$29 -> #REF! | AQ16: =AO16/$AO$95 -> #REF! | AR16: =AO16/$AO$96 -> #REF!
B17: ='Activity data -Head Office'!A14 -> Gasohol 95 รถยนต์ขนาดใหญ่ ขนาด 2000cc ของบริษัท (1ขญ 1643, 2ขญ 1643, 34DUMMY, 4กฎ 2234, 4ขต 9545) | C17: ='Activity data -Head Office'!E14 -> Litre | D17: ='Activity data -Head Office'!F14 -> 4724.45 | E17: =#REF! -> #REF! | F17: =#REF! -> #REF! | G17: =#REF! -> #REF! | H17: =#REF! -> #REF! | I17: 0 | J17: 0 | K17: 0 | L17: 0 | M17: 0 | N17: 0 | Q17: =(E17*$AV$8)+(F17*$AV$9)+(G17*$AV$10)+(H17*$AV$11)+(I17*$AV$12)+(J17*$AV$13)+(K17*M17)+(L17*N17) -> #REF! | U17: x | Z17: EF_CFO_Gasoline [Moblie combustion] | AA17: =D17*E17/1000 -> #REF! | AB17: =D17*F17/1000 -> #REF! | AC17: =D17*G17/1000 -> #REF! | AD17: =D17*H17/1000 -> #REF! | AE17: =D17*I17/1000 -> 0 | AF17: =D17*J17/1000 -> 0 | AG17: =D17*F17*$AV$9/1000 -> #REF! | AH17: =D17*G17*$AV$10/1000 -> #REF! | AI17: =D17*H17*$AV$11/1000 -> #REF! | AJ17: =D17*I17*$AV$12/1000 -> 0 | AK17: =D17*J17*$AV$13/1000 -> 0 | AL17: =D17*K17*M17/1000 -> 0 | AM17: =D17*L17*N17/1000 -> 0 | AO17: =D17*Q17/1000 -> #REF! | AP17: =AO17/$AO$29 -> #REF! | AQ17: =AO17/$AO$95 -> #REF! | AR17: =AO17/$AO$96 -> #REF!
B18: ='Activity data -Head Office'!A15 -> Gasohol 95 รถตู้ของบริษัท (2ขล 9545, ฎค9779, ฎพ9779, ฮฐ6328) | C18: ='Activity data -Head Office'!E15 -> Litre | D18: ='Activity data -Head Office'!F15 -> 7559.43 | E18: =#REF! -> #REF! | F18: =#REF! -> #REF! | G18: =#REF! -> #REF! | H18: =#REF! -> #REF! | I18: 0 | J18: 0 | K18: 0 | L18: 0 | M18: 0 | N18: 0 | Q18: =(E18*$AV$8)+(F18*$AV$9)+(G18*$AV$10)+(H18*$AV$11)+(I18*$AV$12)+(J18*$AV$13)+(K18*M18)+(L18*N18) -> #REF! | U18: x | Z18: EF_CFO_Gasoline [Moblie combustion] | AA18: =D18*E18/1000 -> #REF! | AB18: =D18*F18/1000 -> #REF! | AC18: =D18*G18/1000 -> #REF! | AD18: =D18*H18/1000 -> #REF! | AE18: =D18*I18/1000 -> 0 | AF18: =D18*J18/1000 -> 0 | AG18: =D18*F18*$AV$9/1000 -> #REF! | AH18: =D18*G18*$AV$10/1000 -> #REF! | AI18: =D18*H18*$AV$11/1000 -> #REF! | AJ18: =D18*I18*$AV$12/1000 -> 0 | AK18: =D18*J18*$AV$13/1000 -> 0 | AL18: =D18*K18*M18/1000 -> 0 | AM18: =D18*L18*N18/1000 -> 0 | AO18: =D18*Q18/1000 -> #REF! | AP18: =AO18/$AO$29 -> #REF! | AQ18: =AO18/$AO$95 -> #REF! | AR18: =AO18/$AO$96 -> #REF!
B19: 3.การปล่อยก๊าซเรือนกระจกที่เกิดขึ้นจากกระบวนการผลิต (Industrtial process) | AA19: =D19*E19/1000 -> 0 | AB19: =D19*F19/1000 -> 0 | AC19: =D19*G19/1000 -> 0 | AD19: =D19*H19/1000 -> 0 | AE19: =D19*I19/1000 -> 0 | AF19: =D19*J19/1000 -> 0 | AG19: =D19*F19*$AV$9/1000 -> 0 | AH19: =D19*G19*$AV$10/1000 -> 0 | AI19: =D19*H19*$AV$11/1000 -> 0 | AJ19: =D19*I19*$AV$12/1000 -> 0 | AK19: =D19*J19*$AV$13/1000 -> 0 | AL19: =D19*K19*M19/1000 -> 0 | AM19: =D19*L19*N19/1000 -> 0 | AO19: =D19*Q19/1000 -> 0 | AP19: =AO19/$AO$29 -> #REF! | AQ19: =AO19/$AO$95 -> #REF! | AR19: =AO19/$AO$96 -> #REF!
B20: n/a | AA20: =D20*E20/1000 -> 0 | AB20: =D20*F20/1000 -> 0 | AC20: =D20*G20/1000 -> 0 | AD20: =D20*H20/1000 -> 0 | AE20: =D20*I20/1000 -> 0 | AF20: =D20*J20/1000 -> 0 | AG20: =D20*F20*$AV$9/1000 -> 0 | AH20: =D20*G20*$AV$10/1000 -> 0 | AI20: =D20*H20*$AV$11/1000 -> 0 | AJ20: =D20*I20*$AV$12/1000 -> 0 | AK20: =D20*J20*$AV$13/1000 -> 0 | AL20: =D20*K20*M20/1000 -> 0 | AM20: =D20*L20*N20/1000 -> 0 | AO20: =D20*Q20/1000 -> 0 | AP20: =AO20/$AO$29 -> #REF! | AQ20: =AO20/$AO$95 -> #REF! | AR20: =AO20/$AO$96 -> #REF!
B21: 4. การปล่อยก๊าซเรือนกระจกที่เกิดขึ้นจากการรั่วไหลและอื่นๆ (Fugitive Emission) | AA21: =D21*E21/1000 -> 0 | AB21: =D21*F21/1000 -> 0 | AC21: =D21*G21/1000 -> 0 | AD21: =D21*H21/1000 -> 0 | AE21: =D21*I21/1000 -> 0 | AF21: =D21*J21/1000 -> 0 | AG21: =D21*F21*$AV$9/1000 -> 0 | AH21: =D21*G21*$AV$10/1000 -> 0 | AI21: =D21*H21*$AV$11/1000 -> 0 | AJ21: =D21*I21*$AV$12/1000 -> 0 | AK21: =D21*J21*$AV$13/1000 -> 0 | AL21: =D21*K21*M21/1000 -> 0 | AM21: =D21*L21*N21/1000 -> 0 | AO21: =D21*Q21/1000 -> 0 | AP21: =AO21/$AO$29 -> #REF! | AQ21: =AO21/$AO$95 -> #REF! | AR21: =AO21/$AO$96 -> #REF!
B22: Refrigerant | AA22: =D22*E22/1000 -> 0 | AB22: =D22*F22/1000 -> 0 | AC22: =D22*G22/1000 -> 0 | AD22: =D22*H22/1000 -> 0 | AE22: =D22*I22/1000 -> 0 | AF22: =D22*J22/1000 -> 0 | AG22: =D22*F22*$AV$9/1000 -> 0 | AH22: =D22*G22*$AV$10/1000 -> 0 | AI22: =D22*H22*$AV$11/1000 -> 0 | AJ22: =D22*I22*$AV$12/1000 -> 0 | AK22: =D22*J22*$AV$13/1000 -> 0 | AL22: =D22*K22*M22/1000 -> 0 | AM22: =D22*L22*N22/1000 -> 0 | AO22: =D22*Q22/1000 -> 0 | AP22: =AO22/$AO$29 -> #REF! | AQ22: =AO22/$AO$95 -> #REF! | AR22: =AO22/$AO$96 -> #REF!
B23: ='Activity data -Head Office'!A20 -> HFC-32 | C23: ='Activity data -Head Office'!E20 -> kg/year | D23: ='Activity data -Head Office'!F20 -> 2.761 | E23: 0 | F23: 0 | G23: 0 | H23: 0 | I23: 0 | J23: 0 | K23: 1 | L23: 0 | M23: 677 | N23: 0 | Q23: =(E23*$AV$8)+(F23*$AV$9)+(G23*$AV$10)+(H23*$AV$11)+(I23*$AV$12)+(J23*$AV$13)+(K23*M23)+(L23*N23) -> 677 | U23: x | Z23: EF_CFO_Refrigerants | AA23: =D23*E23/1000 -> 0 | AB23: =D23*F23/1000 -> 0 | AC23: =D23*G23/1000 -> 0 | AD23: =D23*H23/1000 -> 0 | AE23: =D23*I23/1000 -> 0 | AF23: =D23*J23/1000 -> 0 | AG23: =D23*F23*$AV$9/1000 -> 0 | AH23: =D23*G23*$AV$10/1000 -> 0 | AI23: =D23*H23*$AV$11/1000 -> 0 | AJ23: =D23*I23*$AV$12/1000 -> 0 | AK23: =D23*J23*$AV$13/1000 -> 0 | AL23: =D23*K23*M23/1000 -> 1.869197 | AM23: =D23*L23*N23/1000 -> 0 | AO23: =D23*Q23/1000 -> 1.869197 | AP23: =AO23/$AO$29 -> #REF! | AQ23: =AO23/$AO$95 -> #REF! | AR23: =AO23/$AO$96 -> #REF!
B24: ='Activity data -Head Office'!A21 -> HFC-410a | C24: ='Activity data -Head Office'!E21 -> kg/year | D24: ='Activity data -Head Office'!F21 -> 0.28 | E24: 0 | F24: 0 | G24: 0 | H24: 0 | I24: 0 | J24: 0 | K24: 1 | L24: 0 | M24: 1923.5 | N24: 0 | Q24: =(E24*$AV$8)+(F24*$AV$9)+(G24*$AV$10)+(H24*$AV$11)+(I24*$AV$12)+(J24*$AV$13)+(K24*M24)+(L24*N24) -> 1923.5 | X24: x | Z24: IPCC 2013_Fifth Assesment Report (AR5)[HFC32 :50%, HFC125:50%] | AA24: =D24*E24/1000 -> 0 | AB24: =D24*F24/1000 -> 0 | AC24: =D24*G24/1000 -> 0 | AD24: =D24*H24/1000 -> 0 | AE24: =D24*I24/1000 -> 0 | AF24: =D24*J24/1000 -> 0 | AG24: =D24*F24*$AV$9/1000 -> 0 | AH24: =D24*G24*$AV$10/1000 -> 0 | AI24: =D24*H24*$AV$11/1000 -> 0 | AJ24: =D24*I24*$AV$12/1000 -> 0 | AK24: =D24*J24*$AV$13/1000 -> 0 | AL24: =D24*K24*M24/1000 -> 0.53858 | AM24: =D24*L24*N24/1000 -> 0 | AO24: =D24*Q24/1000 -> 0.53858 | AP24: =AO24/$AO$29 -> #REF! | AQ24: =AO24/$AO$95 -> #REF! | AR24: =AO24/$AO$96 -> #REF!
B25: ='Activity data -Head Office'!A23 -> สารดับเพลิงชนิด CO2 (ไม่มีการใช้งาน) | C25: ='Activity data -Head Office'!E23 -> kg/year | D25: ='Activity data -Head Office'!F23 -> 0 | E25: 1 | F25: 0 | G25: 0 | H25: 0 | I25: 0 | J25: 0 | K25: 1 | L25: 0 | M25: 0 | N25: 0 | Q25: =(E25*$AV$8)+(F25*$AV$9)+(G25*$AV$10)+(H25*$AV$11)+(I25*$AV$12)+(J25*$AV$13)+(K25*M25)+(L25*N25) -> 1 | X25: x | Z25: IPCC 2013_Fifth Assesment Report (AR5) | AA25: =D25*E25/1000 -> 0 | AB25: =D25*F25/1000 -> 0 | AC25: =D25*G25/1000 -> 0 | AD25: =D25*H25/1000 -> 0 | AE25: =D25*I25/1000 -> 0 | AF25: =D25*J25/1000 -> 0 | AG25: =D25*F25*$AV$9/1000 -> 0 | AH25: =D25*G25*$AV$10/1000 -> 0 | AI25: =D25*H25*$AV$11/1000 -> 0 | AJ25: =D25*I25*$AV$12/1000 -> 0 | AK25: =D25*J25*$AV$13/1000 -> 0 | AL25: =D25*K25*M25/1000 -> 0 | AM25: =D25*L25*N25/1000 -> 0 | AO25: =D25*Q25/1000 -> 0 | AP25: =AO25/$AO$29 -> #REF! | AQ25: =AO25/$AO$95 -> #REF! | AR25: =AO25/$AO$96 -> #REF!
B26: ='Activity data -Head Office'!A25 -> CH4 from septic tank | C26: ='Activity data -Head Office'!E25 -> kgCH4 | D26: =#REF! -> #REF! | E26: 0 | F26: 0 | G26: 1 | H26: 0 | I26: 0 | J26: 0 | K26: 0 | L26: 0 | M26: 0 | N26: 0 | Q26: =(E26*$AV$8)+(F26*$AV$9)+(G26*$AV$10)+(H26*$AV$11)+(I26*$AV$12)+(J26*$AV$13)+(K26*M26)+(L26*N26) -> 28 | X26: x | Z26: IPCC 2006_Chapter4_Biological Treatment of Solid Waste_Table 4.1 | AA26: =D26*E26/1000 -> #REF! | AB26: =D26*F26/1000 -> #REF! | AC26: =D26*G26/1000 -> #REF! | AD26: =D26*H26/1000 -> #REF! | AE26: =D26*I26/1000 -> #REF! | AF26: =D26*J26/1000 -> #REF! | AG26: =D26*F26*$AV$9/1000 -> #REF! | AH26: =D26*G26*$AV$10/1000 -> #REF! | AI26: =D26*H26*$AV$11/1000 -> #REF! | AJ26: =D26*I26*$AV$12/1000 -> #REF! | AK26: =D26*J26*$AV$13/1000 -> #REF! | AL26: =D26*K26*M26/1000 -> #REF! | AM26: =D26*L26*N26/1000 -> #REF! | AO26: =D26*Q26/1000 -> #REF! | AP26: =AO26/$AO$29 -> #REF! | AQ26: =AO26/$AO$95 -> #REF! | AR26: =AO26/$AO$96 -> #REF!
B27: 5.การปล่อยก๊าซเรือนกระจกจากป่าไม้/ชีวมวล | AA27: =D27*E27/1000 -> 0 | AB27: =D27*F27/1000 -> 0 | AC27: =D27*G27/1000 -> 0 | AD27: =D27*H27/1000 -> 0 | AE27: =D27*I27/1000 -> 0 | AF27: =D27*J27/1000 -> 0 | AG27: =D27*F27*$AV$9/1000 -> 0 | AH27: =D27*G27*$AV$10/1000 -> 0 | AI27: =D27*H27*$AV$11/1000 -> 0 | AJ27: =D27*I27*$AV$12/1000 -> 0 | AK27: =D27*J27*$AV$13/1000 -> 0 | AL27: =D27*K27*M27/1000 -> 0 | AM27: =D27*L27*N27/1000 -> 0 | AO27: =D27*Q27/1000 -> 0 | AP27: =AO27/$AO$29 -> #REF! | AQ27: =AO27/$AO$95 -> #REF! | AR27: =AO27/$AO$96 -> #REF!
B28: n/a | AA28: =D28*E28/1000 -> 0 | AB28: =D28*F28/1000 -> 0 | AC28: =D28*G28/1000 -> 0 | AD28: =D28*H28/1000 -> 0 | AE28: =D28*I28/1000 -> 0 | AF28: =D28*J28/1000 -> 0 | AG28: =D28*F28*$AV$9/1000 -> 0 | AH28: =D28*G28*$AV$10/1000 -> 0 | AI28: =D28*H28*$AV$11/1000 -> 0 | AJ28: =D28*I28*$AV$12/1000 -> 0 | AK28: =D28*J28*$AV$13/1000 -> 0 | AL28: =D28*K28*M28/1000 -> 0 | AM28: =D28*L28*N28/1000 -> 0 | AO28: =D28*Q28/1000 -> 0 | AP28: =AO28/$AO$29 -> #REF! | AQ28: =AO28/$AO$95 -> #REF! | AR28: =AO28/$AO$96 -> #REF!
AA29: =SUM(AA10:AA28) -> #REF! | AB29: =SUM(AB10:AB28) -> #REF! | AC29: =SUM(AC10:AC28) -> #REF! | AD29: =SUM(AD10:AD28) -> #REF! | AE29: =SUM(AE10:AE28) -> #REF! | AF29: =SUM(AF10:AF28) -> #REF! | AG29: =SUM(AG10:AG28) -> #REF! | AH29: =SUM(AH10:AH28) -> #REF! | ... AP29: =SUM(AP10:AP28) -> #REF!
A30: การปล่อย GHG โดยตรงที่ทำการรายงานแยก | E30: 0
A36: ขอบเขต 2 | B36: ='Activity data -Head Office'!A29 -> Electricity power [ไฟฟ้าสำนักงานใหญ่] | C36: ='Activity data -Head Office'!E29 -> Kwh | D36: ='Activity data -Head Office'!F29 -> 166539 | Q36: 0.4999 | U36: x | Z36: EF_CFO_Electricity grid Mix | AO36: =D36*Q36/1000 -> 83.252846 | AP36: =AO36/$AO$40 -> 1 | AQ36: =AO36/$AO$95 -> #REF! | AR36: =AO36/$AO$96 -> #REF!
B37: ='Activity data -Head Office'!A30 -> Electricity power [ไฟฟ้าโซล่าเซลล์]- สำนักงานใหญ่ | C37: ='Activity data -Head Office'!E30 -> Kwh | D37: ='Activity data -Head Office'!F30 -> 61610 | Q37: 0 | AO37: =D37*Q37/1000 -> 0 | AP37: =AO37/$AO$40 -> 0 | AQ37: =AO37/$AO$95 -> #REF! | AR37: =AO37/$AO$96 -> #REF!
AO38: =D38*Q38/1000 -> 0 | AP38: =AO38/$AO$40 -> 0 | AQ38: =AO38/$AO$95 -> #REF! | AR38: =AO38/$AO$96 -> #REF!
AO39: =D39*Q39/1000 -> 0 | AP39: =AO39/$AO$40 -> 0 | AQ39: =AO39/$AO$95 -> #REF! | AR39: =AO39/$AO$96 -> #REF!
AO40: =SUM(AO36:AO39) -> 83.252846 | AP40: =SUM(AP36:AP39) -> 1
A41: ขอบเขต 3 | B41: CAT1: การปล่อยก๊าซเรือนกระจกทางอ้อมจากการซื้อวัตถุดิบ และบริการ (Purchased goods and services) | AO41: =D41*Q41/1000 -> 0 | AP41: =AO41/$AO$94 -> 0 | AR41: =AO41/$AO$96 -> #REF!
B42: n/a | AO42: =D42*Q42/1000 -> 0 | AP42: =AO42/$AO$94 -> 0 | AR42: =AO42/$AO$96 -> #REF!
B43: CAT2: การปล่อยก๊าซเรือนกระจกทางอ้อมจากสินค้าประเภททุน (Capital goods) | AO43: =D43*Q43/1000 -> 0 | AP43: =AO43/$AO$94 -> 0 | AR43: =AO43/$AO$96 -> #REF!
B44: ='Activity data -Head Office'!A36 -> รายการทรัพย์สินที่มูลค่า 5000 บาท และอายุการใช้งาน 3 ปี ขึ้นไป | C44: {='Activity data -Head Office'!E36:F36} -> Baht | D44: 0 | Q44: 0.4267 | U44: x | Z44: EF_CFP_No.51 | AO44: =D44*Q44/1000 -> 0 | AP44: =AO44/$AO$94 -> 0 | AR44: =AO44/$AO$96 -> #REF!
B45: CAT3: การปล่อยก๊าซเรือนกระจกทางอ้อมจากกิจกรรมที่เกี่ยวข้องกับเช้ือเพลิงและพลังงาน (Fuel- and energy related activities) | AO45: =D45*Q45/1000 -> 0 | AP45: =AO45/$AO$94 -> 0 | AR45: =AO45/$AO$96 -> #REF!
B46: ='Activity data -Head Office'!A38 -> Diesel B7 | C46: kg | D46: ='Activity data -Head Office'!S38 -> 12917.295 | Q46: 0.3522 | U46: x | Z46: EF_CFP_No.55 | AO46: =D46*Q46/1000 -> 4.5494714 | AP46: =AO46/$AO$94 -> 0.026687304 | AR46: =AO46/$AO$96 -> #REF!
B47: ='Activity data -Head Office'!A39 -> Gasohol 95 | C47: kg | D47: ='Activity data -Head Office'!S39 -> 9255.9036 | Q47: 0.4024 | U47: x | Z47: EF_CFP_No.52 | AO47: =D47*Q47/1000 -> 3.7245756 | AP47: =AO47/$AO$94 -> 0.021848447 | AR47: =AO47/$AO$96 -> #REF!
...

Sheet Activity data -Head Office
A1: Activity Data Year 2025
A4: แหล่งปล่อยก๊าซเรือนกระจก | B4: หลักฐานอ้างอิง | C4: ผู้รับผิดชอบข้อมูล | D4: หน่วยงานที่รับผิดชอบ | E4: หน่วย | F4: รวม | G4: เดือน
G5: 1 | H5: 2 | I5: 3 | J5: 4 | K5: 5 | L5: 6 | M5: 7 | N5: 8 | O5: 9 | P5: 10 | Q5: 11 | R5: 12
A6: Scope 1: การปล่อยก๊าซเรือนกระจกทางตรงขององค์กร (Direct GHG Emissions)
A7: 1.การปล่อยก๊าซเรือนกระจกที่เกิดขึ้นจากการเผาไหม้อยู่กับที่ (Stationary Combustion)
A8: n/a
A9: 2.การปล่อยก๊าซเรือนกระจกที่เกิดขึ้นจากการเผาไหม้แบบเคลื่อนที่ (Mobile Combustion)
A10: Diesel B7 รถ forklift | B10: Fleetcard | C10: ปัณณรุจ ทองนพเก้า | D10: ฝ่ายบริหารทรัพยากรบุคคลและบริหารสำนักงานส่วนกลาง-HO | E10: Litre | F10: =SUM(G10:R10) -> 627.63 | G10: =31.22+38.5 -> 69.72 | H10: 37.89 | I10: 78.5 | J10: 40.01 | K10: 37.82 | L10: 70.64 | M10: =0+40.64 -> 40.64 | N10: =31.99+0 -> 31.99 | O10: =0+39.7 -> 39.7 | P10: 38.75 | Q10: 72.92 | R10: 69.05
A11: Diesel B7 รถบรรทุก 6 ล้อ (บท9680, 83-9095) | B11: Fleetcard | C11: ปัณณรุจ ทองนพเก้า | D11: ฝ่ายบริหารทรัพยากรบุคคลและบริหารสำนักงานส่วนกลาง-HO | E11: Litre | F11: =SUM(G11:R11) -> 8786.38 | G11: =380.73+457.57 -> 838.3 | H11: =364.76+459.5 -> 824.26 | I11: 847.95 | J11: 661.53 | K11: 761.63 | L11: 772.1 | M11: =190.89+395.63 -> 586.52 | N11: =273.17+368 -> 641.17 | O11: =224.29+472.64 -> 696.93 | P11: =270.53+509.73 -> 780.26 | Q11: 633.08 | R11: 742.65
A12: Diesel B7 รถกระบะส่วนบุคคลขนาด 1 ตัน ของบริษัท (1กร 3494) | B12: Fleetcard | C12: ปัณณรุจ ทองนพเก้า | D12: ฝ่ายบริหารทรัพยากรบุคคลและบริหารสำนักงานส่วนกลาง-HO | E12: Litre | F12: =SUM(G12:R12) -> 2991.31 | G12: 401.94 | H12: 184 | I12: 214.53 | J12: 228.73 | K12: 340.37 | L12: 177.94 | M12: 291.66 | N12: 183.14 | O12: 364.67 | P12: 102.56 | Q12: 233.31 | R12: 268.46
A13: Diesel B7/พรีเมียม รถยนต์ขนาดใหญ่ 2000 cc (4ขอ 1948, 6กญ 2678, ญร4569, ภฮ9789) | B13: Fleetcard | C13: ปัณณรุจ ทองนพเก้า | D13: ฝ่ายบริหารทรัพยากรบุคคลและบริหารสำนักงานส่วนกลาง-HO | E13: Litre | F13: =SUM(G13:R13) -> 2881.42 | G13: =0+0+0+60.33 -> 60.33 | H13: =29.06+59.73+92.45+135.1 -> 316.34 | I13: =27+121.26+0+64.54 -> 212.8 | J13: =0+0+44.01+60.53 -> 104.54 | K13: =33.06+121.08+42.2+135.64 -> 331.98 | L13: =34.12+59.5+88.16+139.05 -> 320.83 | M13: =25.8+57.58+46.26+70.38 -> 200.02 | N13: =0+120.07+44.7+71.66 -> 236.43 | O13: =61.2+59.29+47.2+72.72 -> 240.41 | P13: =140.19+0+121.44+90.83 -> 352.46 | Q13: 275.39 | R13: 229.89
A14: Gasohol 95 รถยนต์ขนาดใหญ่ ขนาด 2000cc ของบริษัท (1ขญ 1643, 2ขญ 1643, 34DUMMY, 4กฎ 2234, 4ขต 9545) | B14: Fleetcard | C14: ปัณณรุจ ทองนพเก้า | D14: ฝ่ายบริหารทรัพยากรบุคคลและบริหารสำนักงานส่วนกลาง-HO | E14: Litre | F14: =SUM(G14:R14) -> 4724.45 | G14: 323.57 | H14: 505.87 | I14: 374.99 | J14: 326.08 | K14: 447.68 | L14: 349.07 | M14: 343.31 | N14: 345.22 | O14: 341.69 | P14: =0+231.85+322.06+53.24 -> 607.15 | Q14: 533.35 | R14: 226.47
A15: Gasohol 95 รถตู้ของบริษัท (2ขล 9545, ฎค9779, ฎพ9779, ฮฐ6328) | B15: Fleetcard | C15: ปัณณรุจ ทองนพเก้า | D15: ฝ่ายบริหารทรัพยากรบุคคลและบริหารสำนักงานส่วนกลาง-HO | E15: Litre | F15: =SUM(G15:R15) -> 7559.43 | G15: =319.8+190.97 -> 510.77 | H15: 745.97 | I15: =428.1+233.67 -> 661.77 | J15: =495.68+314.29 -> 809.97 | K15: =381.74+304.79 -> 686.53 | L15: 662.54 | M15: =334.35+186.32 -> 520.67 | N15: =221.77+221.82 -> 443.59 | O15: =271.96+285.05 -> 557.01 | P15: =318.7+299.97 -> 618.67 | Q15: 556.86 | R15: 785.08
A16: 3.การปล่อยก๊าซเรือนกระจกที่เกิดขึ้นจากกระบวนการผลิต (Industrtial process)
A17: n/a
A18: 4. การปล่อยก๊าซเรือนกระจกที่เกิดขึ้นจากการรั่วไหลและอื่นๆ (Fugitive Emission)
A19: Refrigerant
A20: HFC-32 | B20: คำนวณจากสูตร | C20: ธนบดี | D20: ฝ่ายบริหารยุทธศาสตร์ความยั่งยืน | E20: kg/year | F20: 2.761
A21: HFC-410a | B21: คำนวณจากสูตร | C21: ธนบดี | D21: ฝ่ายบริหารยุทธศาสตร์ความยั่งยืน | E21: kg/year | F21: 0.28
A22: HFC-22 (ไม่รายงาน เนื่องจากไม่อยู่ภายใต้ข้อกำหนดของ อบก.) | B22: รายการตรวจเช็คถังดับเพลิง | C22: ปัณณรุจ ทองนพเก้า | D22: ฝ่ายบริหารทรัพยากรบุคคลและบริหารสำนักงานส่วนกลาง-HO | E22: kg/year
A23: สารดับเพลิงชนิด CO2 (ไม่มีการใช้งาน) | B23: รายการตรวจเช็คถังดับเพลิง | C23: ปัณณรุจ ทองนพเก้า | D23: ฝ่ายบริหารทรัพยากรบุคคลและบริหารสำนักงานส่วนกลาง-HO | E23: kg/year | F23: 0
A24: ถังดับเพลิงชนิดสารเคมีแห้ง HCFC-123 (ไม่มีการรั่วไหล) (ไม่รายงาน เนื่องจากไม่อยู่ภายใต้ข้อกำหนดของ อบก.) | B24: คำนวณจากสูตร | C24: ธนบดี | D24: ฝ่ายบริหารยุทธศาสตร์ความยั่งยืน | E24: kg/year
A25: CH4 from septic tank | B25: MY HR | C25: จิรภัทร ทิพย์จันทร์ | D25: ฝ่ายบริหารทรัพยากรบุคคลและบริหารสำนักงานส่วนกลาง-HO | E25: kgCH4 | F25: =#REF! -> #REF!
A26: 5.การปล่อยก๊าซเรือนกระจกจากป่าไม้/ชีวมวล
A27: n/a
A28: Scope 2: การปล่อยก๊าซเรือนกระจกทางอ้อมจากการใช้พลังงานขององค์กร (Energy Indirect GHG Emissions)
A29: Electricity power [ไฟฟ้าสำนักงานใหญ่] | B29: บิลไฟฟ้า | C29: ปัณณรุจ ทองนพเก้า | D29: ฝ่ายบริหารทรัพยากรบุคคลและบริหารสำนักงานส่วนกลาง-HO | E29: Kwh | F29: =SUM(G29:R29) -> 166539 | G29: 11143 | H29: 11278 | I29: 13808 | J29: 13338 | K29: 13808 | L29: 13419 | M29: 14863 | N29: 15947 | O29: 14166 | P29: 15627 | Q29: 14266 | R29: 14876
A30: Electricity power [ไฟฟ้าโซล่าเซลล์]- สำนักงานใหญ่ | B30: แอพโซล่าร์เซลล์ | C30: ปัณณรุจ ทองนพเก้า | D30: ฝ่ายบริหารทรัพยากรบุคคลและบริหารสำนักงานส่วนกลาง-HO | E30: Kwh | F30: =SUM(G30:R30) -> 61610 | G30: 6390 | H30: 5640 | I30: 6940 | J30: 6810 | K30: 5890 | L30: 6030 | M30: 5030 | N30: 5140 | O30: 4110 | P30: 3640 | Q30: 2650 | R30: 3340
A31: Electricity power [ไฟฟ้ารวมที่องค์กรรับผิดชอบ]-สำนักงานใหญ่ | B31: - | C31: - | D31: - | E31: Kwh | F31: =SUM(G31:R31) -> 166539 | G31: =G29 -> 11143 | H31: =H29 -> 11278 | I31: =I29 -> 13808 | J31: =J29 -> 13338 | K31: =K29 -> 13808 | L31: =L29 -> 13419 | M31: =M29 -> 14863 | N31: =N29 -> 15947 | ... R31: =R29 -> 14876
A32: Scope 3: การปล่อยก๊าซเรือนกระจกทางอ้อมจากกิจกรรมอื่นๆ (Other Indirect Emsiion)
A33: CAT1: การปล่อยก๊าซเรือนกระจกทางอ้อมจากการซื้อวัตถุดิบ และบริการ (Purchased goods and services)
A34: n/a
A35: CAT2: การปล่อยก๊าซเรือนกระจกทางอ้อมจากสินค้าประเภททุน (Capital goods)
A36: รายการทรัพย์สินที่มูลค่า 5000 บาท และอายุการใช้งาน 3 ปี ขึ้นไป | B36: ทะเบียนทรัพย์สิน | C36: สุรชา | D36: ฝ่ายบัญชี-HO | E36: Baht | F36: =SUM(G36:R36) -> 0
A37: CAT3: การปล่อยก๊าซเรือนกระจกทางอ้อมจากกิจกรรมที่เกี่ยวข้องกับเช้ือเพลิงและพลังงาน (Fuel- and energy related activities)
A38: Diesel B7 | B38: คำนวณจากผลรวม | C38: ธนบดี | D38: ฝ่ายบริหารยุทธศาสตร์ความยั่งยืน | E38: Litre | F38: =SUM(G38:R38) -> 15286.74 | G38: =G10+G11+G12+G13 -> 1370.29 | H38: =H10+H11+H12+H13 -> 1362.49 | I38: =I10+I11+I12+I13 -> 1353.78 | J38: =J10+J11+J12+J13 -> 1034.81 | K38: =K10+K11+K12+K13 -> 1471.8 | L38: =L10+L11+L12+L13 -> 1341.51 | M38: =M10+M11+M12+M13 -> 1118.84 | N38: =N10+N11+N12+N13 -> 1092.73 | ... R38: =R10+R11+R12+R13 -> 1310.05 | S38: =F38*0.845 -> 12917.295 | T38: kg
A39: Gasohol 95 | B39: คำนวณจากผลรวม | C39: ธนบดี | D39: ฝ่ายบริหารยุทธศาสตร์ความยั่งยืน | E39: Litre | F39: =SUM(G39:R39) -> 12283.88 | G39: =G14+G15 -> 834.34 | H39: =H14+H15 -> 1251.84 | I39: =I14+I15 -> 1036.76 | J39: =J14+J15 -> 1136.05 | K39: =K14+K15 -> 1134.21 | L39: =L14+L15 -> 1011.61 | M39: =M14+M15 -> 863.98 | N39: =N14+N15 -> 788.81 | ... R39: =R14+R15 -> 1011.55 | S39: =F39*0.7535 -> 9255.9036 | T39: kg
A40: Electricity power | B40: คำนวณจากผลรวม | C40: ธนบดี | D40: ฝ่ายบริหารยุทธศาสตร์ความยั่งยืน | E40: Kwh | F40: =SUM(G40:R40) -> 166539 | G40: =G31 -> 11143 | H40: =H31 -> 11278 | I40: =I31 -> 13808 | J40: =J31 -> 13338 | K40: =K31 -> 13808 | L40: =L31 -> 13419 | M40: =M31 -> 14863 | N40: =N31 -> 15947 | ... R40: =R31 -> 14876
A41: CAT4: การปล่อยก๊าซเรือนกระจกทางออ้มจากการขนส่ง และกระจายสินค้าต้นน้ำ (Upstream transportation and distribution)
A42: n/a
...
